Workbook

Sheet Dashboard
A1: Films Box Office Dashboard
A2: US films from 1980 to 2016 with real gross values. Hit = box office gross at or above production budget (marketing costs not included).
A4: Films analysed | C4: Hit rate | E4: Median return | G4: Total profit
A5: =COUNTIF('Cleaned Data'!$K$2:$K$4847,"Yes") | C5: =AVERAGEIFS('Cleaned Data'!$N$2:$N$4847,'Cleaned Data'!$K$2:$K$4847,"Yes") | E5: {=MEDIAN(IF('Cleaned Data'!$K$2:$K$4847="Yes",'Cleaned Data'!$M$2:$M$4847))} | G5: =SUMIFS('Cleaned Data'!$L$2:$L$4847,'Cleaned Data'!$K$2:$K$4847,"Yes")

Sheet Insights
B1: Films Box Office: Business & Human Insights
B2: Analysis set: 3,087 US films from 1980 to 2016 with real gross values. Hit = gross at or above budget. Supporting figures are in Segment Analysis.
B4: KEY TAKEAWAYS
B5: Only about half of films earn back their budget | C5: Just 55% of films took in at least their budget at the box office, and the median film returned $1.14 per $1 spent. Before marketing and distribution costs, a typical release only just breaks even, so studios rely on a few big winners to cover the rest.
B6: A few films earn most of the money | C6: The top 10% of films brought in about 41% of all box office takings. The business is driven by hits, so managing a slate as a portfolio matters more than any single title.
B7: Smaller budgets give the best returns | C7: Films under $5M had the highest median return (1.71x) and hit rate (59%). Films over $50M returned about 1.0x. Big budgets buy absolute revenue but not better odds. When they fail, the losses are huge: John Carter, Battleship, 47 Ronin and Jack the Giant Slayer each lost more than $130M.
B8: Family-friendly ratings do better | C8: G and PG films hit 63-66% of the time, compared with 53-54% for PG-13 and R. A wider audience (families who buy multiple tickets, plus repeat viewing) turns into steadier returns. R is the most common rating (44% of the set) but the least reliable.
B9: Longer films do better, partly because of what they are | C9: Films over 140 minutes had a 63% hit rate, compared with 52% for films under 90 minutes. Long films are usually prestige or franchise projects with strong source material, so length reflects confidence in the film rather than causing success.
B10: Low-budget horror stands out | C10: Paranormal Activity ($15K budget, $108M gross) and The Blair Witch Project ($60K budget, $141M gross) are the biggest return outliers. Horror is cheap to make, and fans turn out reliably and spread the word, so it is a low-risk way to try new filmmakers and ideas.
B12: HUMAN INSIGHTS (WHY AUDIENCES BEHAVE THIS WAY)
B13: Going to the cinema is a social decision | C13: G and PG films are chosen by groups, often parents with children. One "yes" sells several tickets, which explains their higher median gross despite similar budgets.
B14: Novelty and fear spread by word of mouth | C14: The low-budget horror hits sold an experience ("you have to see this") rather than stars or spectacle. Audiences reward originality when the marketing makes the film feel like an event.
B15: Spectacle alone does not win audiences | C15: Several $175M+ flops relied on effects and unfamiliar source material. Audiences pay for stories and characters they already care about, not the size of the budget.
B16: Viewers are getting more selective | C16: Median returns fell from about 3x in the 1980s to about 1.0-1.1x in the 2000s and 2010s, while releases per year grew to more than 200. More choice (and later, streaming) spreads audience attention more thinly.
B18: RECOMMENDATIONS
B19: 1. Manage the slate as a portfolio | C19: Fund several micro- and low-budget titles (under $5M) for each tentpole. Each small film costs little if it fails and can return 100x or more if it catches on.
B20: 2. Set a higher bar for $100M+ projects | C20: Approve tentpoles only with proven IP, a family-friendly rating plan and international pre-sales. Their hit rate is no better than average and the losses are the largest.
B21: 3. Aim for PG or PG-13 where the story allows | C21: Moving a film from R to PG-13 widens its audience. Only target R when the genre (horror, adult drama) needs it and the budget is kept low.
B22: 4. Invest in genres that build word of mouth | C22: Horror and original concepts at low budgets give the best return for the risk. Spend on event-style marketing rather than production.
B24: DATA CLEANING DONE
B25: Header row restored | C25: Row 1 held a garbled film record instead of column names. Proper headers were added and the record (Intolerance, 1916) was restored as a data row.
B26: 122 duplicates removed | C26: Rows repeating the same title and year were removed, keeping the first occurrence.
B27: 790 imputed gross values flagged | C27: Gross values filled with the median (25,529,689.5), plus 1 missing, are flagged in the Gross Imputed column and excluded from all revenue figures.
B28: Text "nan" placeholders blanked | C28: Missing ratings, languages and countries stored as the text "nan" are now true blanks.
B29: Analysis limited to US films from 1980 | C29: Non-US budgets are in local currencies (The Host: 12.2B KRW), and pre-1980 films are too few to compare.
B30: Known limitations | C30: Gross is box office only (no streaming, home video or marketing costs). The Polar Express gross ($0.67M) is a source error. Results show patterns, not causes.

Sheet Segment Analysis
A1: Segment Analysis: US films from 1980, real gross values only
A2: All figures are live formulas on Cleaned Data, filtered to In Analysis Set = Yes. Return = gross / budget. Hit = gross at or above budget. Median return is an array formula.
A4: Budget tier | B4: Films | C4: Hit rate | D4: Median return | E4: Total budget | F4: Total gross | G4: Total profit
A5: Under $5M | B5: =COUNTIFS('Cleaned Data'!$K$2:$K$4847,"Yes",'Cleaned Data'!$O$2:$O$4847,$A5) | C5: =IFERROR(AVERAGEIFS('Cleaned Data'!$N$2:$N$4847,'Cleaned Data'!$K$2:$K$4847,"Yes",'Cleaned Data'!$O$2:$O$4847,$A5),0) | D5: {=MEDIAN(IF(('Cleaned Data'!$K$2:$K$4847="Yes")*('Cleaned Data'!$O$2:$O$4847=$A5),'Cleaned Data'!$M$2:$M$4847))} | E5: =SUMIFS('Cleaned Data'!$I$2:$I$4847,'Cleaned Data'!$K$2:$K$4847,"Yes",'Cleaned Data'!$O$2:$O$4847,$A5) | F5: =SUMIFS('Cleaned Data'!$H$2:$H$4847,'Cleaned Data'!$K$2:$K$4847,"Yes",'Cleaned Data'!$O$2:$O$4847,$A5) | G5: =SUMIFS('Cleaned Data'!$L$2:$L$4847,'Cleaned Data'!$K$2:$K$4847,"Yes",'Cleaned Data'!$O$2:$O$4847,$A5)
A6: $5M-20M | B6: =COUNTIFS('Cleaned Data'!$K$2:$K$4847,"Yes",'Cleaned Data'!$O$2:$O$4847,$A6) | C6: =IFERROR(AVERAGEIFS('Cleaned Data'!$N$2:$N$4847,'Cleaned Data'!$K$2:$K$4847,"Yes",'Cleaned Data'!$O$2:$O$4847,$A6),0) | D6: {=MEDIAN(IF(('Cleaned Data'!$K$2:$K$4847="Yes")*('Cleaned Data'!$O$2:$O$4847=$A6),'Cleaned Data'!$M$2:$M$4847))} | E6: =SUMIFS('Cleaned Data'!$I$2:$I$4847,'Cleaned Data'!$K$2:$K$4847,"Yes",'Cleaned Data'!$O$2:$O$4847,$A6) | F6: =SUMIFS('Cleaned Data'!$H$2:$H$4847,'Cleaned Data'!$K$2:$K$4847,"Yes",'Cleaned Data'!$O$2:$O$4847,$A6) | G6: =SUMIFS('Cleaned Data'!$L$2:$L$4847,'Cleaned Data'!$K$2:$K$4847,"Yes",'Cleaned Data'!$O$2:$O$4847,$A6)
A7: $20M-50M | B7: =COUNTIFS('Cleaned Data'!$K$2:$K$4847,"Yes",'Cleaned Data'!$O$2:$O$4847,$A7) | C7: =IFERROR(AVERAGEIFS('Cleaned Data'!$N$2:$N$4847,'Cleaned Data'!$K$2:$K$4847,"Yes",'Cleaned Data'!$O$2:$O$4847,$A7),0) | D7: {=MEDIAN(IF(('Cleaned Data'!$K$2:$K$4847="Yes")*('Cleaned Data'!$O$2:$O$4847=$A7),'Cleaned Data'!$M$2:$M$4847))} | E7: =SUMIFS('Cleaned Data'!$I$2:$I$4847,'Cleaned Data'!$K$2:$K$4847,"Yes",'Cleaned Data'!$O$2:$O$4847,$A7) | F7: =SUMIFS('Cleaned Data'!$H$2:$H$4847,'Cleaned Data'!$K$2:$K$4847,"Yes",'Cleaned Data'!$O$2:$O$4847,$A7) | G7: =SUMIFS('Cleaned Data'!$L$2:$L$4847,'Cleaned Data'!$K$2:$K$4847,"Yes",'Cleaned Data'!$O$2:$O$4847,$A7)
A8: $50M-100M | B8: =COUNTIFS('Cleaned Data'!$K$2:$K$4847,"Yes",'Cleaned Data'!$O$2:$O$4847,$A8) | C8: =IFERROR(AVERAGEIFS('Cleaned Data'!$N$2:$N$4847,'Cleaned Data'!$K$2:$K$4847,"Yes",'Cleaned Data'!$O$2:$O$4847,$A8),0) | D8: {=MEDIAN(IF(('Cleaned Data'!$K$2:$K$4847="Yes")*('Cleaned Data'!$O$2:$O$4847=$A8),'Cleaned Data'!$M$2:$M$4847))} | E8: =SUMIFS('Cleaned Data'!$I$2:$I$4847,'Cleaned Data'!$K$2:$K$4847,"Yes",'Cleaned Data'!$O$2:$O$4847,$A8) | F8: =SUMIFS('Cleaned Data'!$H$2:$H$4847,'Cleaned Data'!$K$2:$K$4847,"Yes",'Cleaned Data'!$O$2:$O$4847,$A8) | G8: =SUMIFS('Cleaned Data'!$L$2:$L$4847,'Cleaned Data'!$K$2:$K$4847,"Yes",'Cleaned Data'!$O$2:$O$4847,$A8)
A9: $100M+ | B9: =COUNTIFS('Cleaned Data'!$K$2:$K$4847,"Yes",'Cleaned Data'!$O$2:$O$4847,$A9) | C9: =IFERROR(AVERAGEIFS('Cleaned Data'!$N$2:$N$4847,'Cleaned Data'!$K$2:$K$4847,"Yes",'Cleaned Data'!$O$2:$O$4847,$A9),0) | D9: {=MEDIAN(IF(('Cleaned Data'!$K$2:$K$4847="Yes")*('Cleaned Data'!$O$2:$O$4847=$A9),'Cleaned Data'!$M$2:$M$4847))} | E9: =SUMIFS('Cleaned Data'!$I$2:$I$4847,'Cleaned Data'!$K$2:$K$4847,"Yes",'Cleaned Data'!$O$2:$O$4847,$A9) | F9: =SUMIFS('Cleaned Data'!$H$2:$H$4847,'Cleaned Data'!$K$2:$K$4847,"Yes",'Cleaned Data'!$O$2:$O$4847,$A9) | G9: =SUMIFS('Cleaned Data'!$L$2:$L$4847,'Cleaned Data'!$K$2:$K$4847,"Yes",'Cleaned Data'!$O$2:$O$4847,$A9)
A11: Rating | B11: Films | C11: Hit rate | D11: Median return | E11: Total budget | F11: Total gross | G11: Total profit
A12: G | B12: =COUNTIFS('Cleaned Data'!$K$2:$K$4847,"Yes",'Cleaned Data'!$G$2:$G$4847,$A12) | C12: =IFERROR(AVERAGEIFS('Cleaned Data'!$N$2:$N$4847,'Cleaned Data'!$K$2:$K$4847,"Yes",'Cleaned Data'!$G$2:$G$4847,$A12),0) | D12: {=MEDIAN(IF(('Cleaned Data'!$K$2:$K$4847="Yes")*('Cleaned Data'!$G$2:$G$4847=$A12),'Cleaned Data'!$M$2:$M$4847))} | E12: =SUMIFS('Cleaned Data'!$I$2:$I$4847,'Cleaned Data'!$K$2:$K$4847,"Yes",'Cleaned Data'!$G$2:$G$4847,$A12) | F12: =SUMIFS('Cleaned Data'!$H$2:$H$4847,'Cleaned Data'!$K$2:$K$4847,"Yes",'Cleaned Data'!$G$2:$G$4847,$A12) | G12: =SUMIFS('Cleaned Data'!$L$2:$L$4847,'Cleaned Data'!$K$2:$K$4847,"Yes",'Cleaned Data'!$G$2:$G$4847,$A12)
A13: PG | B13: =COUNTIFS('Cleaned Data'!$K$2:$K$4847,"Yes",'Cleaned Data'!$G$2:$G$4847,$A13) | C13: =IFERROR(AVERAGEIFS('Cleaned Data'!$N$2:$N$4847,'Cleaned Data'!$K$2:$K$4847,"Yes",'Cleaned Data'!$G$2:$G$4847,$A13),0) | D13: {=MEDIAN(IF(('Cleaned Data'!$K$2:$K$4847="Yes")*('Cleaned Data'!$G$2:$G$4847=$A13),'Cleaned Data'!$M$2:$M$4847))} | E13: =SUMIFS('Cleaned Data'!$I$2:$I$4847,'Cleaned Data'!$K$2:$K$4847,"Yes",'Cleaned Data'!$G$2:$G$4847,$A13) | F13: =SUMIFS('Cleaned Data'!$H$2:$H$4847,'Cleaned Data'!$K$2:$K$4847,"Yes",'Cleaned Data'!$G$2:$G$4847,$A13) | G13: =SUMIFS('Cleaned Data'!$L$2:$L$4847,'Cleaned Data'!$K$2:$K$4847,"Yes",'Cleaned Data'!$G$2:$G$4847,$A13)
A14: PG-13 | B14: =COUNTIFS('Cleaned Data'!$K$2:$K$4847,"Yes",'Cleaned Data'!$G$2:$G$4847,$A14) | C14: =IFERROR(AVERAGEIFS('Cleaned Data'!$N$2:$N$4847,'Cleaned Data'!$K$2:$K$4847,"Yes",'Cleaned Data'!$G$2:$G$4847,$A14),0) | D14: {=MEDIAN(IF(('Cleaned Data'!$K$2:$K$4847="Yes")*('Cleaned Data'!$G$2:$G$4847=$A14),'Cleaned Data'!$M$2:$M$4847))} | E14: =SUMIFS('Cleaned Data'!$I$2:$I$4847,'Cleaned Data'!$K$2:$K$4847,"Yes",'Cleaned Data'!$G$2:$G$4847,$A14) | F14: =SUMIFS('Cleaned Data'!$H$2:$H$4847,'Cleaned Data'!$K$2:$K$4847,"Yes",'Cleaned Data'!$G$2:$G$4847,$A14) | G14: =SUMIFS('Cleaned Data'!$L$2:$L$4847,'Cleaned Data'!$K$2:$K$4847,"Yes",'Cleaned Data'!$G$2:$G$4847,$A14)
A15: R | B15: =COUNTIFS('Cleaned Data'!$K$2:$K$4847,"Yes",'Cleaned Data'!$G$2:$G$4847,$A15) | C15: =IFERROR(AVERAGEIFS('Cleaned Data'!$N$2:$N$4847,'Cleaned Data'!$K$2:$K$4847,"Yes",'Cleaned Data'!$G$2:$G$4847,$A15),0) | D15: {=MEDIAN(IF(('Cleaned Data'!$K$2:$K$4847="Yes")*('Cleaned Data'!$G$2:$G$4847=$A15),'Cleaned Data'!$M$2:$M$4847))} | E15: =SUMIFS('Cleaned Data'!$I$2:$I$4847,'Cleaned Data'!$K$2:$K$4847,"Yes",'Cleaned Data'!$G$2:$G$4847,$A15) | F15: =SUMIFS('Cleaned Data'!$H$2:$H$4847,'Cleaned Data'!$K$2:$K$4847,"Yes",'Cleaned Data'!$G$2:$G$4847,$A15) | G15: =SUMIFS('Cleaned Data'!$L$2:$L$4847,'Cleaned Data'!$K$2:$K$4847,"Yes",'Cleaned Data'!$G$2:$G$4847,$A15)
A17: Runtime (min) | B17: Films | C17: Hit rate | D17: Median return | E17: Total budget | F17: Total gross | G17: Total profit
A18: 90 or less | B18: =COUNTIFS('Cleaned Data'!$K$2:$K$4847,"Yes",'Cleaned Data'!$P$2:$P$4847,$A18) | C18: =IFERROR(AVERAGEIFS('Cleaned Data'!$N$2:$N$4847,'Cleaned Data'!$K$2:$K$4847,"Yes",'Cleaned Data'!$P$2:$P$4847,$A18),0) | D18: {=MEDIAN(IF(('Cleaned Data'!$K$2:$K$4847="Yes")*('Cleaned Data'!$P$2:$P$4847=$A18),'Cleaned Data'!$M$2:$M$4847))} | E18: =SUMIFS('Cleaned Data'!$I$2:$I$4847,'Cleaned Data'!$K$2:$K$4847,"Yes",'Cleaned Data'!$P$2:$P$4847,$A18) | F18: =SUMIFS('Cleaned Data'!$H$2:$H$4847,'Cleaned Data'!$K$2:$K$4847,"Yes",'Cleaned Data'!$P$2:$P$4847,$A18) | G18: =SUMIFS('Cleaned Data'!$L$2:$L$4847,'Cleaned Data'!$K$2:$K$4847,"Yes",'Cleaned Data'!$P$2:$P$4847,$A18)
A19: 91-105 | B19: =COUNTIFS('Cleaned Data'!$K$2:$K$4847,"Yes",'Cleaned Data'!$P$2:$P$4847,$A19) | C19: =IFERROR(AVERAGEIFS('Cleaned Data'!$N$2:$N$4847,'Cleaned Data'!$K$2:$K$4847,"Yes",'Cleaned Data'!$P$2:$P$4847,$A19),0) | D19: {=MEDIAN(IF(('Cleaned Data'!$K$2:$K$4847="Yes")*('Cleaned Data'!$P$2:$P$4847=$A19),'Cleaned Data'!$M$2:$M$4847))} | E19: =SUMIFS('Cleaned Data'!$I$2:$I$4847,'Cleaned Data'!$K$2:$K$4847,"Yes",'Cleaned Data'!$P$2:$P$4847,$A19) | F19: =SUMIFS('Cleaned Data'!$H$2:$H$4847,'Cleaned Data'!$K$2:$K$4847,"Yes",'Cleaned Data'!$P$2:$P$4847,$A19) | G19: =SUMIFS('Cleaned Data'!$L$2:$L$4847,'Cleaned Data'!$K$2:$K$4847,"Yes",'Cleaned Data'!$P$2:$P$4847,$A19)
A20: 106-120 | B20: =COUNTIFS('Cleaned Data'!$K$2:$K$4847,"Yes",'Cleaned Data'!$P$2:$P$4847,$A20) | C20: =IFERROR(AVERAGEIFS('Cleaned Data'!$N$2:$N$4847,'Cleaned Data'!$K$2:$K$4847,"Yes",'Cleaned Data'!$P$2:$P$4847,$A20),0) | D20: {=MEDIAN(IF(('Cleaned Data'!$K$2:$K$4847="Yes")*('Cleaned Data'!$P$2:$P$4847=$A20),'Cleaned Data'!$M$2:$M$4847))} | E20: =SUMIFS('Cleaned Data'!$I$2:$I$4847,'Cleaned Data'!$K$2:$K$4847,"Yes",'Cleaned Data'!$P$2:$P$4847,$A20) | F20: =SUMIFS('Cleaned Data'!$H$2:$H$4847,'Cleaned Data'!$K$2:$K$4847,"Yes",'Cleaned Data'!$P$2:$P$4847,$A20) | G20: =SUMIFS('Cleaned Data'!$L$2:$L$4847,'Cleaned Data'!$K$2:$K$4847,"Yes",'Cleaned Data'!$P$2:$P$4847,$A20)
A21: 121-140 | B21: =COUNTIFS('Cleaned Data'!$K$2:$K$4847,"Yes",'Cleaned Data'!$P$2:$P$4847,$A21) | C21: =IFERROR(AVERAGEIFS('Cleaned Data'!$N$2:$N$4847,'Cleaned Data'!$K$2:$K$4847,"Yes",'Cleaned Data'!$P$2:$P$4847,$A21),0) | D21: {=MEDIAN(IF(('Cleaned Data'!$K$2:$K$4847="Yes")*('Cleaned Data'!$P$2:$P$4847=$A21),'Cleaned Data'!$M$2:$M$4847))} | E21: =SUMIFS('Cleaned Data'!$I$2:$I$4847,'Cleaned Data'!$K$2:$K$4847,"Yes",'Cleaned Data'!$P$2:$P$4847,$A21) | F21: =SUMIFS('Cleaned Data'!$H$2:$H$4847,'Cleaned Data'!$K$2:$K$4847,"Yes",'Cleaned Data'!$P$2:$P$4847,$A21) | G21: =SUMIFS('Cleaned Data'!$L$2:$L$4847,'Cleaned Data'!$K$2:$K$4847,"Yes",'Cleaned Data'!$P$2:$P$4847,$A21)
A22: Over 140 | B22: =COUNTIFS('Cleaned Data'!$K$2:$K$4847,"Yes",'Cleaned Data'!$P$2:$P$4847,$A22) | C22: =IFERROR(AVERAGEIFS('Cleaned Data'!$N$2:$N$4847,'Cleaned Data'!$K$2:$K$4847,"Yes",'Cleaned Data'!$P$2:$P$4847,$A22),0) | D22: {=MEDIAN(IF(('Cleaned Data'!$K$2:$K$4847="Yes")*('Cleaned Data'!$P$2:$P$4847=$A22),'Cleaned Data'!$M$2:$M$4847))} | E22: =SUMIFS('Cleaned Data'!$I$2:$I$4847,'Cleaned Data'!$K$2:$K$4847,"Yes",'Cleaned Data'!$P$2:$P$4847,$A22) | F22: =SUMIFS('Cleaned Data'!$H$2:$H$4847,'Cleaned Data'!$K$2:$K$4847,"Yes",'Cleaned Data'!$P$2:$P$4847,$A22) | G22: =SUMIFS('Cleaned Data'!$L$2:$L$4847,'Cleaned Data'!$K$2:$K$4847,"Yes",'Cleaned Data'!$P$2:$P$4847,$A22)
A24: Decade | B24: Films | C24: Hit rate | D24: Median return | E24: Total budget | F24: Total gross | G24: Total profit
A25: 1980 | B25: =COUNTIFS('Cleaned Data'!$K$2:$K$4847,"Yes",'Cleaned Data'!$Q$2:$Q$4847,$A25) | C25: =IFERROR(AVERAGEIFS('Cleaned Data'!$N$2:$N$4847,'Cleaned Data'!$K$2:$K$4847,"Yes",'Cleaned Data'!$Q$2:$Q$4847,$A25),0) | D25: {=MEDIAN(IF(('Cleaned Data'!$K$2:$K$4847="Yes")*('Cleaned Data'!$Q$2:$Q$4847=$A25),'Cleaned Data'!$M$2:$M$4847))} | E25: =SUMIFS('Cleaned Data'!$I$2:$I$4847,'Cleaned Data'!$K$2:$K$4847,"Yes",'Cleaned Data'!$Q$2:$Q$4847,$A25) | F25: =SUMIFS('Cleaned Data'!$H$2:$H$4847,'Cleaned Data'!$K$2:$K$4847,"Yes",'Cleaned Data'!$Q$2:$Q$4847,$A25) | G25: =SUMIFS('Cleaned Data'!$L$2:$L$4847,'Cleaned Data'!$K$2:$K$4847,"Yes",'Cleaned Data'!$Q$2:$Q$4847,$A25)
A26: 1990 | B26: =COUNTIFS('Cleaned Data'!$K$2:$K$4847,"Yes",'Cleaned Data'!$Q$2:$Q$4847,$A26) | C26: =IFERROR(AVERAGEIFS('Cleaned Data'!$N$2:$N$4847,'Cleaned Data'!$K$2:$K$4847,"Yes",'Cleaned Data'!$Q$2:$Q$4847,$A26),0) | D26: {=MEDIAN(IF(('Cleaned Data'!$K$2:$K$4847="Yes")*('Cleaned Data'!$Q$2:$Q$4847=$A26),'Cleaned Data'!$M$2:$M$4847))} | E26: =SUMIFS('Cleaned Data'!$I$2:$I$4847,'Cleaned Data'!$K$2:$K$4847,"Yes",'Cleaned Data'!$Q$2:$Q$4847,$A26) | F26: =SUMIFS('Cleaned Data'!$H$2:$H$4847,'Cleaned Data'!$K$2:$K$4847,"Yes",'Cleaned Data'!$Q$2:$Q$4847,$A26) | G26: =SUMIFS('Cleaned Data'!$L$2:$L$4847,'Cleaned Data'!$K$2:$K$4847,"Yes",'Cleaned Data'!$Q$2:$Q$4847,$A26)
A27: 2000 | B27: =COUNTIFS('Cleaned Data'!$K$2:$K$4847,"Yes",'Cleaned Data'!$Q$2:$Q$4847,$A27) | C27: =IFERROR(AVERAGEIFS('Cleaned Data'!$N$2:$N$4847,'Cleaned Data'!$K$2:$K$4847,"Yes",'Cleaned Data'!$Q$2:$Q$4847,$A27),0) | D27: {=MEDIAN(IF(('Cleaned Data'!$K$2:$K$4847="Yes")*('Cleaned Data'!$Q$2:$Q$4847=$A27),'Cleaned Data'!$M$2:$M$4847))} | E27: =SUMIFS('Cleaned Data'!$I$2:$I$4847,'Cleaned Data'!$K$2:$K$4847,"Yes",'Cleaned Data'!$Q$2:$Q$4847,$A27) | F27: =SUMIFS('Cleaned Data'!$H$2:$H$4847,'Cleaned Data'!$K$2:$K$4847,"Yes",'Cleaned Data'!$Q$2:$Q$4847,$A27) | G27: =SUMIFS('Cleaned Data'!$L$2:$L$4847,'Cleaned Data'!$K$2:$K$4847,"Yes",'Cleaned Data'!$Q$2:$Q$4847,$A27)
A28: 2010 | B28: =COUNTIFS('Cleaned Data'!$K$2:$K$4847,"Yes",'Cleaned Data'!$Q$2:$Q$4847,$A28) | C28: =IFERROR(AVERAGEIFS('Cleaned Data'!$N$2:$N$4847,'Cleaned Data'!$K$2:$K$4847,"Yes",'Cleaned Data'!$Q$2:$Q$4847,$A28),0) | D28: {=MEDIAN(IF(('Cleaned Data'!$K$2:$K$4847="Yes")*('Cleaned Data'!$Q$2:$Q$4847=$A28),'Cleaned Data'!$M$2:$M$4847))} | E28: =SUMIFS('Cleaned Data'!$I$2:$I$4847,'Cleaned Data'!$K$2:$K$4847,"Yes",'Cleaned Data'!$Q$2:$Q$4847,$A28) | F28: =SUMIFS('Cleaned Data'!$H$2:$H$4847,'Cleaned Data'!$K$2:$K$4847,"Yes",'Cleaned Data'!$Q$2:$Q$4847,$A28) | G28: =SUMIFS('Cleaned Data'!$L$2:$L$4847,'Cleaned Data'!$K$2:$K$4847,"Yes",'Cleaned Data'!$Q$2:$Q$4847,$A28)

Sheet Data Quality
A1: Data Quality Log
A3: Check | B3: Result | C3: Action taken
A4: Films in cleaned dataset | B4: =COUNTA('Cleaned Data'!B2:B4847) | C4: Source had 4,968 records; header row restored
A5: Duplicate title + year rows removed | B5: 122 | C5: Removed in cleaning (kept first occurrence). Hardcoded: count from the cleaning script
A6: Gross filled with median (25,529,689.5) or missing | B6: =COUNTIF('Cleaned Data'!J2:J4847,"Yes") | C6: Flagged in Gross Imputed and excluded from revenue analysis
A7: Share of films with imputed gross | B7: =B6/B4 | C7: Too large to ignore: it would bias averages toward the median
A8: Budget exactly 20,000,000 | B8: =COUNTIF('Cleaned Data'!I2:I4847,20000000) | C8: Kept: a common real budget, but may hide more imputation
A9: Budgets above 1 billion (local currency) | B9: =COUNTIF('Cleaned Data'!I2:I4847,">1000000000") | C9: Non-US budgets in KRW/JPY/HUF; analysis limited to US films
A10: Runtime under 40 minutes | B10: =COUNTIF('Cleaned Data'!E2:E4847,"<40") | C10: Kept: shorts or entry errors, small effect on results
A11: Missing rating | B11: =COUNTBLANK('Cleaned Data'!G2:G4847) | C11: Kept: shown as blank; excluded from the rating segment
A12: Missing language | B12: =COUNTBLANK('Cleaned Data'!F2:F4847) | C12: Text "nan" placeholders converted to blanks
A13: Films in analysis set | B13: =COUNTIF('Cleaned Data'!K2:K4847,"Yes") | C13: US, 1980 or later, real gross
A15: Known value error: The Polar Express (2004) shows a gross of $0.67M; the real US gross was over $180M. Left as-is to keep the source traceable.

Sheet Cleaned Data
A1: ID | B1: Title | C1: Year | D1: Country | E1: Duration (min) | F1: Language | G1: Rating | H1: Gross (USD) | I1: Budget (local currency) | J1: Gross Imputed | K1: In Analysis Set | L1: Profit | M1: Return (x) | N1: Hit | O1: Budget Tier | P1: Runtime Band | Q1: Decade
A2: 1 | B2: Intolerance: Love's Struggle Throughout the Ages | C2: 1916 | D2: USA | E2: 123 | G2: Not Rated | I2: 385907 | J2: =IF(OR(H2="",H2=25529689.5),"Yes","No") | K2: =IF(AND(D2="USA",C2>=1980,J2="No"),"Yes","No") | L2: =IF(J2="Yes","",H2-I2) | M2: =IF(OR(J2="Yes",I2=0),"",H2/I2) | N2: =IF(J2="Yes","",IF(H2>=I2,1,0)) | O2: =IF(I2<=5000000,"Under $5M",IF(I2<=20000000,"$5M-20M",IF(I2<=50000000,"$20M-50M",IF(I2<=100000000,"$50M-100M","$100M+")))) | P2: =IF(E2<=90,"90 or less",IF(E2<=105,"91-105",IF(E2<=120,"106-120",IF(E2<=140,"121-140","Over 140")))) | Q2: =INT(C2/10)*10
A3: 2 | B3: Over the Hill to the Poorhouse | C3: 1920 | D3: USA | E3: 110 | H3: 3000000 | I3: 100000 | J3: =IF(OR(H3="",H3=25529689.5),"Yes","No") | K3: =IF(AND(D3="USA",C3>=1980,J3="No"),"Yes","No") | L3: =IF(J3="Yes","",H3-I3) | M3: =IF(OR(J3="Yes",I3=0),"",H3/I3) | N3: =IF(J3="Yes","",IF(H3>=I3,1,0)) | O3: =IF(I3<=5000000,"Under $5M",IF(I3<=20000000,"$5M-20M",IF(I3<=50000000,"$20M-50M",IF(I3<=100000000,"$50M-100M","$100M+")))) | P3: =IF(E3<=90,"90 or less",IF(E3<=105,"91-105",IF(E3<=120,"106-120",IF(E3<=140,"121-140","Over 140")))) | Q3: =INT(C3/10)*10
A4: 3 | B4: The Big Parade | C4: 1925 | D4: USA | E4: 151 | G4: Not Rated | H4: 25529690 | I4: 245000 | J4: =IF(OR(H4="",H4=25529689.5),"Yes","No") | K4: =IF(AND(D4="USA",C4>=1980,J4="No"),"Yes","No") | L4: =IF(J4="Yes","",H4-I4) | M4: =IF(OR(J4="Yes",I4=0),"",H4/I4) | N4: =IF(J4="Yes","",IF(H4>=I4,1,0)) | O4: =IF(I4<=5000000,"Under $5M",IF(I4<=20000000,"$5M-20M",IF(I4<=50000000,"$20M-50M",IF(I4<=100000000,"$50M-100M","$100M+")))) | P4: =IF(E4<=90,"90 or less",IF(E4<=105,"91-105",IF(E4<=120,"106-120",IF(E4<=140,"121-140","Over 140")))) | Q4: =INT(C4/10)*10
A5: 4 | B5: Metropolis | C5: 1927 | D5: Germany | E5: 145 | F5: German | G5: Not Rated | H5: 26435 | I5: 6000000 | J5: =IF(OR(H5="",H5=25529689.5),"Yes","No") | K5: =IF(AND(D5="USA",C5>=1980,J5="No"),"Yes","No") | L5: =IF(J5="Yes","",H5-I5) | M5: =IF(OR(J5="Yes",I5=0),"",H5/I5) | N5: =IF(J5="Yes","",IF(H5>=I5,1,0)) | O5: =IF(I5<=5000000,"Under $5M",IF(I5<=20000000,"$5M-20M",IF(I5<=50000000,"$20M-50M",IF(I5<=100000000,"$50M-100M","$100M+")))) | P5: =IF(E5<=90,"90 or less",IF(E5<=105,"91-105",IF(E5<=120,"106-120",IF(E5<=140,"121-140","Over 140")))) | Q5: =INT(C5/10)*10
A6: 5 | B6: Pandora's Box | C6: 1929 | D6: Germany | E6: 110 | F6: German | G6: Not Rated | H6: 9950 | I6: 20000000 | J6: =IF(OR(H6="",H6=25529689.5),"Yes","No") | K6: =IF(AND(D6="USA",C6>=1980,J6="No"),"Yes","No") | L6: =IF(J6="Yes","",H6-I6) | M6: =IF(OR(J6="Yes",I6=0),"",H6/I6) | N6: =IF(J6="Yes","",IF(H6>=I6,1,0)) | O6: =IF(I6<=5000000,"Under $5M",IF(I6<=20000000,"$5M-20M",IF(I6<=50000000,"$20M-50M",IF(I6<=100000000,"$50M-100M","$100M+")))) | P6: =IF(E6<=90,"90 or less",IF(E6<=105,"91-105",IF(E6<=120,"106-120",IF(E6<=140,"121-140","Over 140")))) | Q6: =INT(C6/10)*10
A7: 6 | B7: The Broadway Melody | C7: 1929 | D7: USA | E7: 100 | F7: English | G7: Passed | H7: 2808000 | I7: 379000 | J7: =IF(OR(H7="",H7=25529689.5),"Yes","No") | K7: =IF(AND(D7="USA",C7>=1980,J7="No"),"Yes","No") | L7: =IF(J7="Yes","",H7-I7) | M7: =IF(OR(J7="Yes",I7=0),"",H7/I7) | N7: =IF(J7="Yes","",IF(H7>=I7,1,0)) | O7: =IF(I7<=5000000,"Under $5M",IF(I7<=20000000,"$5M-20M",IF(I7<=50000000,"$20M-50M",IF(I7<=100000000,"$50M-100M","$100M+")))) | P7: =IF(E7<=90,"90 or less",IF(E7<=105,"91-105",IF(E7<=120,"106-120",IF(E7<=140,"121-140","Over 140")))) | Q7: =INT(C7/10)*10
A8: 7 | B8: Hell's Angels | C8: 1930 | D8: USA | E8: 96 | F8: English | G8: Passed | H8: 25529690 | I8: 3950000 | J8: =IF(OR(H8="",H8=25529689.5),"Yes","No") | K8: =IF(AND(D8="USA",C8>=1980,J8="No"),"Yes","No") | L8: =IF(J8="Yes","",H8-I8) | M8: =IF(OR(J8="Yes",I8=0),"",H8/I8) | N8: =IF(J8="Yes","",IF(H8>=I8,1,0)) | O8: =IF(I8<=5000000,"Under $5M",IF(I8<=20000000,"$5M-20M",IF(I8<=50000000,"$20M-50M",IF(I8<=100000000,"$50M-100M","$100M+")))) | P8: =IF(E8<=90,"90 or less",IF(E8<=105,"91-105",IF(E8<=120,"106-120",IF(E8<=140,"121-140","Over 140")))) | Q8: =INT(C8/10)*10
A9: 8 | B9: A Farewell to Arms | C9: 1932 | D9: USA | E9: 79 | F9: English | G9: Unrated | H9: 25529690 | I9: 800000 | J9: =IF(OR(H9="",H9=25529689.5),"Yes","No") | K9: =IF(AND(D9="USA",C9>=1980,J9="No"),"Yes","No") | L9: =IF(J9="Yes","",H9-I9) | M9: =IF(OR(J9="Yes",I9=0),"",H9/I9) | N9: =IF(J9="Yes","",IF(H9>=I9,1,0)) | O9: =IF(I9<=5000000,"Under $5M",IF(I9<=20000000,"$5M-20M",IF(I9<=50000000,"$20M-50M",IF(I9<=100000000,"$50M-100M","$100M+")))) | P9: =IF(E9<=90,"90 or less",IF(E9<=105,"91-105",IF(E9<=120,"106-120",IF(E9<=140,"121-140","Over 140")))) | Q9: =INT(C9/10)*10
A10: 9 | B10: 42nd Street | C10: 1933 | D10: USA | E10: 89 | F10: English | G10: Unrated | H10: 2300000 | I10: 439000 | J10: =IF(OR(H10="",H10=25529689.5),"Yes","No") | K10: =IF(AND(D10="USA",C10>=1980,J10="No"),"Yes","No") | L10: =IF(J10="Yes","",H10-I10) | M10: =IF(OR(J10="Yes",I10=0),"",H10/I10) | N10: =IF(J10="Yes","",IF(H10>=I10,1,0)) | O10: =IF(I10<=5000000,"Under $5M",IF(I10<=20000000,"$5M-20M",IF(I10<=50000000,"$20M-50M",IF(I10<=100000000,"$50M-100M","$100M+")))) | P10: =IF(E10<=90,"90 or less",IF(E10<=105,"91-105",IF(E10<=120,"106-120",IF(E10<=140,"121-140","Over 140")))) | Q10: =INT(C10/10)*10
A11: 10 | B11: She Done Him Wrong | C11: 1933 | D11: USA | E11: 66 | F11: English | G11: Approved | H11: 25529690 | I11: 200000 | J11: =IF(OR(H11="",H11=25529689.5),"Yes","No") | K11: =IF(AND(D11="USA",C11>=1980,J11="No"),"Yes","No") | L11: =IF(J11="Yes","",H11-I11) | M11: =IF(OR(J11="Yes",I11=0),"",H11/I11) | N11: =IF(J11="Yes","",IF(H11>=I11,1,0)) | O11: =IF(I11<=5000000,"Under $5M",IF(I11<=20000000,"$5M-20M",IF(I11<=50000000,"$20M-50M",IF(I11<=100000000,"$50M-100M","$100M+")))) | P11: =IF(E11<=90,"90 or less",IF(E11<=105,"91-105",IF(E11<=120,"106-120",IF(E11<=140,"121-140","Over 140")))) | Q11: =INT(C11/10)*10
A12: 11 | B12: It Happened One Night | C12: 1934 | D12: USA | E12: 65 | F12: English | G12: Unrated | H12: 25529690 | I12: 325000 | J12: =IF(OR(H12="",H12=25529689.5),"Yes","No") | K12: =IF(AND(D12="USA",C12>=1980,J12="No"),"Yes","No") | L12: =IF(J12="Yes","",H12-I12) | M12: =IF(OR(J12="Yes",I12=0),"",H12/I12) | N12: =IF(J12="Yes","",IF(H12>=I12,1,0)) | O12: =IF(I12<=5000000,"Under $5M",IF(I12<=20000000,"$5M-20M",IF(I12<=50000000,"$20M-50M",IF(I12<=100000000,"$50M-100M","$100M+")))) | P12: =IF(E12<=90,"90 or less",IF(E12<=105,"91-105",IF(E12<=120,"106-120",IF(E12<=140,"121-140","Over 140")))) | Q12: =INT(C12/10)*10
A13: 12 | B13: Top Hat | C13: 1935 | D13: USA | E13: 81 | F13: English | G13: Approved | H13: 3000000 | I13: 609000 | J13: =IF(OR(H13="",H13=25529689.5),"Yes","No") | K13: =IF(AND(D13="USA",C13>=1980,J13="No"),"Yes","No") | L13: =IF(J13="Yes","",H13-I13) | M13: =IF(OR(J13="Yes",I13=0),"",H13/I13) | N13: =IF(J13="Yes","",IF(H13>=I13,1,0)) | O13: =IF(I13<=5000000,"Under $5M",IF(I13<=20000000,"$5M-20M",IF(I13<=50000000,"$20M-50M",IF(I13<=100000000,"$50M-100M","$100M+")))) | P13: =IF(E13<=90,"90 or less",IF(E13<=105,"91-105",IF(E13<=120,"106-120",IF(E13<=140,"121-140","Over 140")))) | Q13: =INT(C13/10)*10
A14: 13 | B14: Modern Times | C14: 1936 | D14: USA | E14: 87 | F14: English | G14: G | H14: 163245 | I14: 1500000 | J14: =IF(OR(H14="",H14=25529689.5),"Yes","No") | K14: =IF(AND(D14="USA",C14>=1980,J14="No"),"Yes","No") | L14: =IF(J14="Yes","",H14-I14) | M14: =IF(OR(J14="Yes",I14=0),"",H14/I14) | N14: =IF(J14="Yes","",IF(H14>=I14,1,0)) | O14: =IF(I14<=5000000,"Under $5M",IF(I14<=20000000,"$5M-20M",IF(I14<=50000000,"$20M-50M",IF(I14<=100000000,"$50M-100M","$100M+")))) | P14: =IF(E14<=90,"90 or less",IF(E14<=105,"91-105",IF(E14<=120,"106-120",IF(E14<=140,"121-140","Over 140")))) | Q14: =INT(C14/10)*10
A15: 14 | B15: The Charge of the Light Brigade | C15: 1936 | D15: USA | E15: 100 | F15: English | G15: Approved | H15: 25529690 | I15: 1200000 | J15: =IF(OR(H15="",H15=25529689.5),"Yes","No") | K15: =IF(AND(D15="USA",C15>=1980,J15="No"),"Yes","No") | L15: =IF(J15="Yes","",H15-I15) | M15: =IF(OR(J15="Yes",I15=0),"",H15/I15) | N15: =IF(J15="Yes","",IF(H15>=I15,1,0)) | O15: =IF(I15<=5000000,"Under $5M",IF(I15<=20000000,"$5M-20M",IF(I15<=50000000,"$20M-50M",IF(I15<=100000000,"$50M-100M","$100M+")))) | P15: =IF(E15<=90,"90 or less",IF(E15<=105,"91-105",IF(E15<=120,"106-120",IF(E15<=140,"121-140","Over 140")))) | Q15: =INT(C15/10)*10
A16: 15 | B16: Snow White and the Seven Dwarfs | C16: 1937 | D16: USA | E16: 83 | F16: English | G16: Approved | H16: 184925485 | I16: 2000000 | J16: =IF(OR(H16="",H16=25529689.5),"Yes","No") | K16: =IF(AND(D16="USA",C16>=1980,J16="No"),"Yes","No") | L16: =IF(J16="Yes","",H16-I16) | M16: =IF(OR(J16="Yes",I16=0),"",H16/I16) | N16: =IF(J16="Yes","",IF(H16>=I16,1,0)) | O16: =IF(I16<=5000000,"Under $5M",IF(I16<=20000000,"$5M-20M",IF(I16<=50000000,"$20M-50M",IF(I16<=100000000,"$50M-100M","$100M+")))) | P16: =IF(E16<=90,"90 or less",IF(E16<=105,"91-105",IF(E16<=120,"106-120",IF(E16<=140,"121-140","Over 140")))) | Q16: =INT(C16/10)*10
... A51: 50 | B51: Show Boat | C51: 1951 | D51: USA | E51: 108 | F51: English | G51: Approved | H51: 25529690 | I51: 2295429 | J51: =IF(OR(H51="",H51=25529689.5),"Yes","No") | K51: =IF(AND(D51="USA",C51>=1980,J51="No"),"Yes","No") | L51: =IF(J51="Yes","",H51-I51) | M51: =IF(OR(J51="Yes",I51=0),"",H51/I51) | N51: =IF(J51="Yes","",IF(H51>=I51,1,0)) | O51: =IF(I51<=5000000,"Under $5M",IF(I51<=20000000,"$5M-20M",IF(I51<=50000000,"$20M-50M",IF(I51<=100000000,"$50M-100M","$100M+")))) | P51: =IF(E51<=90,"90 or less",IF(E51<=105,"91-105",IF(E51<=120,"106-120",IF(E51<=140,"121-140","Over 140")))) | Q51: =INT(C51/10)*10
A52: 51 | B52: Deadline - U.S.A. | C52: 1952 | D52: USA | E52: 87 | F52: English | H52: 25529690 | I52: 20000000 | J52: =IF(OR(H52="",H52=25529689.5),"Yes","No") | K52: =IF(AND(D52="USA",C52>=1980,J52="No"),"Yes","No") | L52: =IF(J52="Yes","",H52-I52) | M52: =IF(OR(J52="Yes",I52=0),"",H52/I52) | N52: =IF(J52="Yes","",IF(H52>=I52,1,0)) | O52: =IF(I52<=5000000,"Under $5M",IF(I52<=20000000,"$5M-20M",IF(I52<=50000000,"$20M-50M",IF(I52<=100000000,"$50M-100M","$100M+")))) | P52: =IF(E52<=90,"90 or less",IF(E52<=105,"91-105",IF(E52<=120,"106-120",IF(E52<=140,"121-140","Over 140")))) | Q52: =INT(C52/10)*10
A53: 52 | B53: High Noon | C53: 1952 | D53: USA | E53: 85 | F53: English | G53: PG | H53: 25529690 | I53: 750000 | J53: =IF(OR(H53="",H53=25529689.5),"Yes","No") | K53: =IF(AND(D53="USA",C53>=1980,J53="No"),"Yes","No") | L53: =IF(J53="Yes","",H53-I53) | M53: =IF(OR(J53="Yes",I53=0),"",H53/I53) | N53: =IF(J53="Yes","",IF(H53>=I53,1,0)) | O53: =IF(I53<=5000000,"Under $5M",IF(I53<=20000000,"$5M-20M",IF(I53<=50000000,"$20M-50M",IF(I53<=100000000,"$50M-100M","$100M+")))) | P53: =IF(E53<=90,"90 or less",IF(E53<=105,"91-105",IF(E53<=120,"106-120",IF(E53<=140,"121-140","Over 140")))) | Q53: =INT(C53/10)*10
A54: 53 | B54: Singin' in the Rain | C54: 1952 | D54: USA | E54: 103 | F54: English | G54: Approved | H54: 25529690 | I54: 2540800 | J54: =IF(OR(H54="",H54=25529689.5),"Yes","No") | K54: =IF(AND(D54="USA",C54>=1980,J54="No"),"Yes","No") | L54: =IF(J54="Yes","",H54-I54) | M54: =IF(OR(J54="Yes",I54=0),"",H54/I54) | N54: =IF(J54="Yes","",IF(H54>=I54,1,0)) | O54: =IF(I54<=5000000,"Under $5M",IF(I54<=20000000,"$5M-20M",IF(I54<=50000000,"$20M-50M",IF(I54<=100000000,"$50M-100M","$100M+")))) | P54: =IF(E54<=90,"90 or less",IF(E54<=105,"91-105",IF(E54<=120,"106-120",IF(E54<=140,"121-140","Over 140")))) | Q54: =INT(C54/10)*10
A55: 54 | B55: The Greatest Show on Earth | C55: 1952 | D55: USA | E55: 152 | F55: English | G55: Not Rated | H55: 36000000 | I55: 4000000 | J55: =IF(OR(H55="",H55=25529689.5),"Yes","No") | K55: =IF(AND(D55="USA",C55>=1980,J55="No"),"Yes","No") | L55: =IF(J55="Yes","",H55-I55) | M55: =IF(OR(J55="Yes",I55=0),"",H55/I55) | N55: =IF(J55="Yes","",IF(H55>=I55,1,0)) | O55: =IF(I55<=5000000,"Under $5M",IF(I55<=20000000,"$5M-20M",IF(I55<=50000000,"$20M-50M",IF(I55<=100000000,"$50M-100M","$100M+")))) | P55: =IF(E55<=90,"90 or less",IF(E55<=105,"91-105",IF(E55<=120,"106-120",IF(E55<=140,"121-140","Over 140")))) | Q55: =INT(C55/10)*10
A56: 55 | B56: From Here to Eternity | C56: 1953 | D56: USA | E56: 118 | F56: English | G56: Not Rated | H56: 25529690 | I56: 1650000 | J56: =IF(OR(H56="",H56=25529689.5),"Yes","No") | K56: =IF(AND(D56="USA",C56>=1980,J56="No"),"Yes","No") | L56: =IF(J56="Yes","",H56-I56) | M56: =IF(OR(J56="Yes",I56=0),"",H56/I56) | N56: =IF(J56="Yes","",IF(H56>=I56,1,0)) | O56: =IF(I56<=5000000,"Under $5M",IF(I56<=20000000,"$5M-20M",IF(I56<=50000000,"$20M-50M",IF(I56<=100000000,"$50M-100M","$100M+")))) | P56: =IF(E56<=90,"90 or less",IF(E56<=105,"91-105",IF(E56<=120,"106-120",IF(E56<=140,"121-140","Over 140")))) | Q56: =INT(C56/10)*10
A57: 56 | B57: Niagara | C57: 1953 | D57: USA | E57: 92 | F57: English | G57: Approved | H57: 25529690 | I57: 1250000 | J57: =IF(OR(H57="",H57=25529689.5),"Yes","No") | K57: =IF(AND(D57="USA",C57>=1980,J57="No"),"Yes","No") | L57: =IF(J57="Yes","",H57-I57) | M57: =IF(OR(J57="Yes",I57=0),"",H57/I57) | N57: =IF(J57="Yes","",IF(H57>=I57,1,0)) | O57: =IF(I57<=5000000,"Under $5M",IF(I57<=20000000,"$5M-20M",IF(I57<=50000000,"$20M-50M",IF(I57<=100000000,"$50M-100M","$100M+")))) | P57: =IF(E57<=90,"90 or less",IF(E57<=105,"91-105",IF(E57<=120,"106-120",IF(E57<=140,"121-140","Over 140")))) | Q57: =INT(C57/10)*10
A58: 57 | B58: The Beast from 20,000 Fathoms | C58: 1953 | D58: USA | E58: 80 | F58: English | G58: Approved | H58: 5000000 | I58: 210000 | J58: =IF(OR(H58="",H58=25529689.5),"Yes","No") | K58: =IF(AND(D58="USA",C58>=1980,J58="No"),"Yes","No") | L58: =IF(J58="Yes","",H58-I58) | M58: =IF(OR(J58="Yes",I58=0),"",H58/I58) | N58: =IF(J58="Yes","",IF(H58>=I58,1,0)) | O58: =IF(I58<=5000000,"Under $5M",IF(I58<=20000000,"$5M-20M",IF(I58<=50000000,"$20M-50M",IF(I58<=100000000,"$50M-100M","$100M+")))) | P58: =IF(E58<=90,"90 or less",IF(E58<=105,"91-105",IF(E58<=120,"106-120",IF(E58<=140,"121-140","Over 140")))) | Q58: =INT(C58/10)*10
A59: 58 | B59: The Robe | C59: 1953 | D59: USA | E59: 135 | F59: English | G59: Unrated | H59: 36000000 | I59: 5000000 | J59: =IF(OR(H59="",H59=25529689.5),"Yes","No") | K59: =IF(AND(D59="USA",C59>=1980,J59="No"),"Yes","No") | L59: =IF(J59="Yes","",H59-I59) | M59: =IF(OR(J59="Yes",I59=0),"",H59/I59) | N59: =IF(J59="Yes","",IF(H59>=I59,1,0)) | O59: =IF(I59<=5000000,"Under $5M",IF(I59<=20000000,"$5M-20M",IF(I59<=50000000,"$20M-50M",IF(I59<=100000000,"$50M-100M","$100M+")))) | P59: =IF(E59<=90,"90 or less",IF(E59<=105,"91-105",IF(E59<=120,"106-120",IF(E59<=140,"121-140","Over 140")))) | Q59: =INT(C59/10)*10
A60: 59 | B60: 20,000 Leagues Under the Sea | C60: 1954 | D60: USA | E60: 127 | F60: English | G60: Approved | H60: 25529690 | I60: 5000000 | J60: =IF(OR(H60="",H60=25529689.5),"Yes","No") | K60: =IF(AND(D60="USA",C60>=1980,J60="No"),"Yes","No") | L60: =IF(J60="Yes","",H60-I60) | M60: =IF(OR(J60="Yes",I60=0),"",H60/I60) | N60: =IF(J60="Yes","",IF(H60>=I60,1,0)) | O60: =IF(I60<=5000000,"Under $5M",IF(I60<=20000000,"$5M-20M",IF(I60<=50000000,"$20M-50M",IF(I60<=100000000,"$50M-100M","$100M+")))) | P60: =IF(E60<=90,"90 or less",IF(E60<=105,"91-105",IF(E60<=120,"106-120",IF(E60<=140,"121-140","Over 140")))) | Q60: =INT(C60/10)*10
A61: 61 | B61: On the Waterfront | C61: 1954 | D61: USA | E61: 108 | F61: English | G61: Not Rated | H61: 9600000 | I61: 910000 | J61: =IF(OR(H61="",H61=25529689.5),"Yes","No") | K61: =IF(AND(D61="USA",C61>=1980,J61="No"),"Yes","No") | L61: =IF(J61="Yes","",H61-I61) | M61: =IF(OR(J61="Yes",I61=0),"",H61/I61) | N61: =IF(J61="Yes","",IF(H61>=I61,1,0)) | O61: =IF(I61<=5000000,"Under $5M",IF(I61<=20000000,"$5M-20M",IF(I61<=50000000,"$20M-50M",IF(I61<=100000000,"$50M-100M","$100M+")))) | P61: =IF(E61<=90,"90 or less",IF(E61<=105,"91-105",IF(E61<=120,"106-120",IF(E61<=140,"121-140","Over 140")))) | Q61: =INT(C61/10)*10
A62: 62 | B62: Seven Samurai | C62: 1954 | D62: Japan | E62: 202 | F62: Japanese | G62: Unrated | H62: 269061 | I62: 2000000 | J62: =IF(OR(H62="",H62=25529689.5),"Yes","No") | K62: =IF(AND(D62="USA",C62>=1980,J62="No"),"Yes","No") | L62: =IF(J62="Yes","",H62-I62) | M62: =IF(OR(J62="Yes",I62=0),"",H62/I62) | N62: =IF(J62="Yes","",IF(H62>=I62,1,0)) | O62: =IF(I62<=5000000,"Under $5M",IF(I62<=20000000,"$5M-20M",IF(I62<=50000000,"$20M-50M",IF(I62<=100000000,"$50M-100M","$100M+")))) | P62: =IF(E62<=90,"90 or less",IF(E62<=105,"91-105",IF(E62<=120,"106-120",IF(E62<=140,"121-140","Over 140")))) | Q62: =INT(C62/10)*10
A63: 63 | B63: The Egyptian | C63: 1954 | D63: USA | E63: 139 | F63: English | G63: Approved | H63: 25529690 | I63: 5000000 | J63: =IF(OR(H63="",H63=25529689.5),"Yes","No") | K63: =IF(AND(D63="USA",C63>=1980,J63="No"),"Yes","No") | L63: =IF(J63="Yes","",H63-I63) | M63: =IF(OR(J63="Yes",I63=0),"",H63/I63) | N63: =IF(J63="Yes","",IF(H63>=I63,1,0)) | O63: =IF(I63<=5000000,"Under $5M",IF(I63<=20000000,"$5M-20M",IF(I63<=50000000,"$20M-50M",IF(I63<=100000000,"$50M-100M","$100M+")))) | P63: =IF(E63<=90,"90 or less",IF(E63<=105,"91-105",IF(E63<=120,"106-120",IF(E63<=140,"121-140","Over 140")))) | Q63: =INT(C63/10)*10
A64: 64 | B64: Ordet | C64: 1955 | D64: Denmark | E64: 126 | F64: Danish | G64: Not Rated | H64: 25529690 | I64: 20000000 | J64: =IF(OR(H64="",H64=25529689.5),"Yes","No") | K64: =IF(AND(D64="USA",C64>=1980,J64="No"),"Yes","No") | L64: =IF(J64="Yes","",H64-I64) | M64: =IF(OR(J64="Yes",I64=0),"",H64/I64) | N64: =IF(J64="Yes","",IF(H64>=I64,1,0)) | O64: =IF(I64<=5000000,"Under $5M",IF(I64<=20000000,"$5M-20M",IF(I64<=50000000,"$20M-50M",IF(I64<=100000000,"$50M-100M","$100M+")))) | P64: =IF(E64<=90,"90 or less",IF(E64<=105,"91-105",IF(E64<=120,"106-120",IF(E64<=140,"121-140","Over 140")))) | Q64: =INT(C64/10)*10
A65: 65 | B65: The Trouble with Harry | C65: 1955 | D65: USA | E65: 99 | F65: English | G65: Approved | H65: 25529690 | I65: 1200000 | J65: =IF(OR(H65="",H65=25529689.5),"Yes","No") | K65: =IF(AND(D65="USA",C65>=1980,J65="No"),"Yes","No") | L65: =IF(J65="Yes","",H65-I65) | M65: =IF(OR(J65="Yes",I65=0),"",H65/I65) | N65: =IF(J65="Yes","",IF(H65>=I65,1,0)) | O65: =IF(I65<=5000000,"Under $5M",IF(I65<=20000000,"$5M-20M",IF(I65<=50000000,"$20M-50M",IF(I65<=100000000,"$50M-100M","$100M+")))) | P65: =IF(E65<=90,"90 or less",IF(E65<=105,"91-105",IF(E65<=120,"106-120",IF(E65<=140,"121-140","Over 140")))) | Q65: =INT(C65/10)*10
A66: 66 | B66: Love Me Tender | C66: 1956 | D66: USA | E66: 89 | F66: English | H66: 25529690 | I66: 1000000 | J66: =IF(OR(H66="",H66=25529689.5),"Yes","No") | K66: =IF(AND(D66="USA",C66>=1980,J66="No"),"Yes","No") | L66: =IF(J66="Yes","",H66-I66) | M66: =IF(OR(J66="Yes",I66=0),"",H66/I66) | N66: =IF(J66="Yes","",IF(H66>=I66,1,0)) | O66: =IF(I66<=5000000,"Under $5M",IF(I66<=20000000,"$5M-20M",IF(I66<=50000000,"$20M-50M",IF(I66<=100000000,"$50M-100M","$100M+")))) | P66: =IF(E66<=90,"90 or less",IF(E66<=105,"91-105",IF(E66<=120,"106-120",IF(E66<=140,"121-140","Over 140")))) | Q66: =INT(C66/10)*10
A67: 67 | B67: Moby Dick | C67: 1956 | D67: USA | E67: 115 | F67: English | G67: Unrated | H67: 25529690 | I67: 4500000 | J67: =IF(OR(H67="",H67=25529689.5),"Yes","No") | K67: =IF(AND(D67="USA",C67>=1980,J67="No"),"Yes","No") | L67: =IF(J67="Yes","",H67-I67) | M67: =IF(OR(J67="Yes",I67=0),"",H67/I67) | N67: =IF(J67="Yes","",IF(H67>=I67,1,0)) | O67: =IF(I67<=5000000,"Under $5M",IF(I67<=20000000,"$5M-20M",IF(I67<=50000000,"$20M-50M",IF(I67<=100000000,"$50M-100M","$100M+")))) | P67: =IF(E67<=90,"90 or less",IF(E67<=105,"91-105",IF(E67<=120,"106-120",IF(E67<=140,"121-140","Over 140")))) | Q67: =INT(C67/10)*10
A68: 68 | B68: Trapeze | C68: 1956 | D68: USA | E68: 105 | F68: English | G68: Approved | H68: 25529690 | I68: 4000000 | J68: =IF(OR(H68="",H68=25529689.5),"Yes","No") | K68: =IF(AND(D68="USA",C68>=1980,J68="No"),"Yes","No") | L68: =IF(J68="Yes","",H68-I68) | M68: =IF(OR(J68="Yes",I68=0),"",H68/I68) | N68: =IF(J68="Yes","",IF(H68>=I68,1,0)) | O68: =IF(I68<=5000000,"Under $5M",IF(I68<=20000000,"$5M-20M",IF(I68<=50000000,"$20M-50M",IF(I68<=100000000,"$50M-100M","$100M+")))) | P68: =IF(E68<=90,"90 or less",IF(E68<=105,"91-105",IF(E68<=120,"106-120",IF(E68<=140,"121-140","Over 140")))) | Q68: =INT(C68/10)*10
A69: 69 | B69: 12 Angry Men | C69: 1957 | D69: USA | E69: 96 | F69: English | G69: Not Rated | H69: 25529690 | I69: 350000 | J69: =IF(OR(H69="",H69=25529689.5),"Yes","No") | K69: =IF(AND(D69="USA",C69>=1980,J69="No"),"Yes","No") | L69: =IF(J69="Yes","",H69-I69) | M69: =IF(OR(J69="Yes",I69=0),"",H69/I69) | N69: =IF(J69="Yes","",IF(H69>=I69,1,0)) | O69: =IF(I69<=5000000,"Under $5M",IF(I69<=20000000,"$5M-20M",IF(I69<=50000000,"$20M-50M",IF(I69<=100000000,"$50M-100M","$100M+")))) | P69: =IF(E69<=90,"90 or less",IF(E69<=105,"91-105",IF(E69<=120,"106-120",IF(E69<=140,"121-140","Over 140")))) | Q69: =INT(C69/10)*10
A70: 70 | B70: The Bridge on the River Kwai | C70: 1957 | D70: UK | E70: 161 | F70: English | G70: PG | H70: 27200000 | I70: 3000000 | J70: =IF(OR(H70="",H70=25529689.5),"Yes","No") | K70: =IF(AND(D70="USA",C70>=1980,J70="No"),"Yes","No") | L70: =IF(J70="Yes","",H70-I70) | M70: =IF(OR(J70="Yes",I70=0),"",H70/I70) | N70: =IF(J70="Yes","",IF(H70>=I70,1,0)) | O70: =IF(I70<=5000000,"Under $5M",IF(I70<=20000000,"$5M-20M",IF(I70<=50000000,"$20M-50M",IF(I70<=100000000,"$50M-100M","$100M+")))) | P70: =IF(E70<=90,"90 or less",IF(E70<=105,"91-105",IF(E70<=120,"106-120",IF(E70<=140,"121-140","Over 140")))) | Q70: =INT(C70/10)*10
A71: 71 | B71: Cat on a Hot Tin Roof | C71: 1958 | D71: USA | E71: 108 | F71: English | G71: Approved | H71: 25529690 | I71: 3000000 | J71: =IF(OR(H71="",H71=25529689.5),"Yes","No") | K71: =IF(AND(D71="USA",C71>=1980,J71="No"),"Yes","No") | L71: =IF(J71="Yes","",H71-I71) | M71: =IF(OR(J71="Yes",I71=0),"",H71/I71) | N71: =IF(J71="Yes","",IF(H71>=I71,1,0)) | O71: =IF(I71<=5000000,"Under $5M",IF(I71<=20000000,"$5M-20M",IF(I71<=50000000,"$20M-50M",IF(I71<=100000000,"$50M-100M","$100M+")))) | P71: =IF(E71<=90,"90 or less",IF(E71<=105,"91-105",IF(E71<=120,"106-120",IF(E71<=140,"121-140","Over 140")))) | Q71: =INT(C71/10)*10
A72: 72 | B72: Solomon and Sheba | C72: 1959 | D72: USA | E72: 141 | F72: English | H72: 25529690 | I72: 5000000 | J72: =IF(OR(H72="",H72=25529689.5),"Yes","No") | K72: =IF(AND(D72="USA",C72>=1980,J72="No"),"Yes","No") | L72: =IF(J72="Yes","",H72-I72) | M72: =IF(OR(J72="Yes",I72=0),"",H72/I72) | N72: =IF(J72="Yes","",IF(H72>=I72,1,0)) | O72: =IF(I72<=5000000,"Under $5M",IF(I72<=20000000,"$5M-20M",IF(I72<=50000000,"$20M-50M",IF(I72<=100000000,"$50M-100M","$100M+")))) | P72: =IF(E72<=90,"90 or less",IF(E72<=105,"91-105",IF(E72<=120,"106-120",IF(E72<=140,"121-140","Over 140")))) | Q72: =INT(C72/10)*10
A73: 73 | B73: Some Like It Hot | C73: 1959 | D73: USA | E73: 120 | F73: English | G73: Not Rated | H73: 25000000 | I73: 2883848 | J73: =IF(OR(H73="",H73=25529689.5),"Yes","No") | K73: =IF(AND(D73="USA",C73>=1980,J73="No"),"Yes","No") | L73: =IF(J73="Yes","",H73-I73) | M73: =IF(OR(J73="Yes",I73=0),"",H73/I73) | N73: =IF(J73="Yes","",IF(H73>=I73,1,0)) | O73: =IF(I73<=5000000,"Under $5M",IF(I73<=20000000,"$5M-20M",IF(I73<=50000000,"$20M-50M",IF(I73<=100000000,"$50M-100M","$100M+")))) | P73: =IF(E73<=90,"90 or less",IF(E73<=105,"91-105",IF(E73<=120,"106-120",IF(E73<=140,"121-140","Over 140")))) | Q73: =INT(C73/10)*10
A74: 74 | B74: The Nun's Story | C74: 1959 | D74: USA | E74: 149 | F74: English | G74: Not Rated | H74: 25529690 | I74: 3500000 | J74: =IF(OR(H74="",H74=25529689.5),"Yes","No") | K74: =IF(AND(D74="USA",C74>=1980,J74="No"),"Yes","No") | L74: =IF(J74="Yes","",H74-I74) | M74: =IF(OR(J74="Yes",I74=0),"",H74/I74) | N74: =IF(J74="Yes","",IF(H74>=I74,1,0)) | O74: =IF(I74<=5000000,"Under $5M",IF(I74<=20000000,"$5M-20M",IF(I74<=50000000,"$20M-50M",IF(I74<=100000000,"$50M-100M","$100M+")))) | P74: =IF(E74<=90,"90 or less",IF(E74<=105,"91-105",IF(E74<=120,"106-120",IF(E74<=140,"121-140","Over 140")))) | Q74: =INT(C74/10)*10
...
